<?xml version="1.0"?>
<robot xmlns:xacro="http://wiki.ros.org/xacro">

  <xacro:property name="PI" value="3.1415926535897931"/>

  <!-- Macro para una rueda -->
  <xacro:macro name="wheel_link" params="name">
    <link name="${name}_link">
      <visual>
        <origin xyz="0 0 0" rpy="0 1.5708 0"/>
        <geometry>
          <mesh filename="package://rover_description/meshes/dae/Torus.002.dae" scale="0.4 0.4 0.6"/>
        </geometry>
        <material name="gray">
          <color rgba="0.6 0.6 0.6 1.0"/>
        </material>
      </visual>
      <collision>
        <origin xyz="0 0 0" rpy="0 1.5708 0"/>
        <geometry>
          <mesh filename="package://rover_description/meshes/dae/Torus.002.dae" scale="0.4 0.4 0.6"/>
        </geometry>
        <surface>
        <friction>
          <ode>
            <mu>1.000000</mu>
            <mu2>1.000000</mu2>
            <fdir1>0.000000 0.000000 1.000000</fdir1>
            <slip1>0.500000</slip1>
            <slip2>0.500000</slip2>
          </ode>
        </friction>
      </surface>

      </collision>
      <inertial>
        <mass value="5"/>
        <origin xyz="0 0 0" rpy="0 0 0"/>
        <inertia ixx="0.31539" ixy="0.0" ixz="0.0"
                 iyy="0.58648" iyz="0.0"
                 izz="0.31539"/>
      </inertial>
    </link>
  </xacro:macro>

  <!-- Macro para el joint de una rueda -->
  <xacro:macro name="wheel_link_joint" params="name xyz rpy parent_link">
    <joint name="${name}_joint" type="continuous">
      <origin xyz="${xyz}" rpy="${rpy}"/>
      <limit effort="5000" velocity="100"/>
      <dynamics damping="0.05" friction="0.1"/>
      <parent link="${parent_link}"/>
      <child link="${name}_link"/>
    </joint>
  </xacro:macro>

  <xacro:macro name="wheel_transmission" params="prefix">
    <transmission name="${prefix}_wheel_joint_trans">
      <type>transmission_interface/SimpleTransmission</type>
      <joint name="${prefix}_wheel_joint">
        <hardwareInterface>hardware_interface/VelocityJointInterface</hardwareInterface>
      </joint>
      <actuator name="${prefix}_wheel_joint_motor">
        <mechanicalReduction>1</mechanicalReduction>
      </actuator>
    </transmission>
  </xacro:macro>

  <xacro:macro name="wheel_gazebo" params="prefix">
    <gazebo reference="${prefix}_wheel_link">
      <mu1>5</mu1>
      <mu2>5</mu2>
      <!--<kd>8.25e1</kd>
      <fdir1>0 0 0</fdir1>
      <maxContacts>4</maxContacts>-->
    </gazebo>
  </xacro:macro>


  <!-- Macro principal para añadir todas las ruedas -->
  <xacro:macro name="rover_wheel" params="prefix">

    <!-- Ruedas delanteras -->
    <xacro:wheel_link name="${prefix}left_front_wheel"/>
    <xacro:wheel_link_joint name="${prefix}left_front_wheel" xyz="1.23688 -0.96147 -0.64379" rpy="0.00000 -0.00000 0.00000" parent_link="base_link"/>
    <xacro:wheel_transmission prefix="${prefix}left_front"/>
    <xacro:wheel_gazebo prefix="${prefix}left_front"/>

    <xacro:wheel_link name="${prefix}right_front_wheel"/>
    <xacro:wheel_link_joint name="${prefix}right_front_wheel" xyz="-1.23028 -0.96147 -0.64379" rpy="0.00000 -0.00000 ${PI}" parent_link="base_link"/>
    <xacro:wheel_transmission prefix="${prefix}right_front"/>
    <xacro:wheel_gazebo prefix="${prefix}right_front"/>

    <!-- Ruedas del medio -->
    <xacro:wheel_link name="${prefix}left_wheel"/>
    <xacro:wheel_link_joint name="${prefix}left_wheel" xyz="1.23688 0.34836 -0.64379" rpy="0.00000 -0.00000 0.00000" parent_link="base_link"/>
    <xacro:wheel_transmission prefix="${prefix}left"/>
    <xacro:wheel_gazebo prefix="${prefix}left"/>

    <xacro:wheel_link name="${prefix}right_wheel"/>
    <xacro:wheel_link_joint name="${prefix}right_wheel" xyz="-1.32480 0.34836 -0.64379" rpy="0.00000 -0.00000 ${PI}" parent_link="base_link"/>
    <xacro:wheel_transmission prefix="${prefix}right"/>
    <xacro:wheel_gazebo prefix="${prefix}right"/>

    <!-- Ruedas traseras -->
    <xacro:wheel_link name="${prefix}left_back_wheel"/>
    <xacro:wheel_link_joint name="${prefix}left_back_wheel" xyz="1.23688 1.71195 -0.64379" rpy="0.00000 -0.00000 0.00000" parent_link="base_link"/>
    <xacro:wheel_transmission prefix="${prefix}left_back"/>
    <xacro:wheel_gazebo prefix="${prefix}left_back"/>

    <xacro:wheel_link name="${prefix}right_back_wheel"/>
    <xacro:wheel_link_joint name="${prefix}right_back_wheel" xyz="-1.23028 1.71195 -0.64379" rpy="0.00000 -0.00000 ${PI}" parent_link="base_link"/>
    <xacro:wheel_transmission prefix="${prefix}right_back"/>
    <xacro:wheel_gazebo prefix="${prefix}right_back"/>


  </xacro:macro>

</robot>



